Workbook
Name AccountTypeList: Settings!$H$2:$H$4
Name CompanyList: Companies!$B$2:$B$50
Name EmployeeList: Employees!$C$2:$C$301
Name EmployeeStatusList: Settings!$N$2:$N$5
Name FilteredEmployeeList: OFFSET(Employees!$U$2,0,0,COUNTIF(Employees!$A$2:$A$301,'Payslip Template'!$B$2),1)
Name PayFrequencyList: Settings!$F$2:$F$4
Name PaymentModeList: Settings!$L$2:$L$4
Name PayPeriodList: 'Payroll Data'!$A$2:$A$1000

Sheet Payslip Template
B1: PAYSLIP | F1: =IFERROR(INDEX(Companies!$J:$J, MATCH($B$2, Companies!$B:$B, 0)), "") -> #VALUE!
B2: =IFERROR(J5, "Alora Dental Care") -> Alora Dental Care | I2: ⚙️ PAYSLIP CONTROLS
D3: =IFERROR(VLOOKUP(B2, Companies!B:J, 3, FALSE()) & IF(VLOOKUP(B2, Companies!B:J, 4, FALSE())<>"", CHAR(10) & VLOOKUP(B2, Companies!B:J, 4, FALSE()), ""), "Suite A4, Financial Square, Entrance 5 Ext 16, eMalahleni, 10359") -> Suite A4, Financial Square, Entrance 5 Ext 16 eMalahleni, 10359 | I3: (Outside A4 Printout — For Controls & Selection)
B4: =IFERROR(VLOOKUP(B2, Companies!B:J, 5, FALSE()), "www.aloradentalcare.co.za") -> www.aloradentalcare.co.za | D4: =IFERROR("[Phone: " & VLOOKUP(B2, Companies!B:J, 6, FALSE()) & "]", "[Phone: (013)656-1067]") -> [Phone: (013)656-1067]
I5: Select Company: | J5: Alora Dental Care
B6: EMPLOYEE | D6: ID NUMBER | E6: TAX REFERENCE NUMBER | F6: EMPLOYEE NUMBER
B7: =IFERROR(J7, "NOMATHEMBA BIANCA MAHLANGU") -> Tintswalo Makhubela | D7: =IFERROR(VLOOKUP(B7, Employees!C:R, 2, FALSE()), "020309 0266 081") -> 940322 0456 083 | E7: =IFERROR(VLOOKUP(B7, Employees!C:R, 3, FALSE()), "") -> 0 | F7: =IFERROR(INDEX(Employees!B:B, MATCH(B7, Employees!C:C, 0)), "NTA002") -> EMP-0004 | I7: Select Employee: | J7: Tintswalo Makhubela
B9: ADDRESS | D9: PHONE | F9: EMAIL | I9: Select Pay Date: | J9: September 2026
B10: =IFERROR(VLOOKUP(B7, Employees!C:R, 6, FALSE()), "942 STOWER STREET, TUSHANANG, EMALAHLENI") -> 49 Duncan Street, Witbank, 1039 | D10: =IFERROR(VLOOKUP(B7, Employees!C:R, 7, FALSE()), "+27 79 184 2503") -> +27 76 123 4567 | F10: =IFERROR(VLOOKUP(B7, Employees!C:R, 8, FALSE()), "nomamahlangu09@gmail.com") -> tintswalo@formalize.co.za
B12: Occupation | D12: PAY DATA | F12: FREQUENCY | I12: 🔄 AUTO-FIT / REFRESH PAYSLIP (Hides 0-value & empty rows)
B13: =IFERROR(VLOOKUP(B7, Employees!C:R, 4, FALSE()), "Trainee Nail Technician") -> Billing Administrator | D13: =IFERROR(TEXT(J9, "dd/mm/yyyy"), "23/12/2025") -> 01/09/2026 | F13: =IFERROR(VLOOKUP(B7, Employees!C:R, 9, FALSE()), "Monthly") -> Monthly
B15: EARNINGS | D15: HOURS/AMOUNT | E15: RATE | F15: TOTAL | I15: 📄 EXPORT TO PDF (A4) (Generates print-ready PDF)
B16: =IFERROR(IF(AND(ISNUMBER(F16), F16>0), "Basic Salary", ""), "") -> Basic Salary | D16: =IFERROR(IF(AND(ISNUMBER(E16), E16>0), 1, ""), "") -> 1 | E16: =IFERROR(INDEX('Payroll Data'!E:E, MATCH(B7, 'Payroll Data'!D:D, 0)), 4885.87) -> 4885.87 | F16: =IFERROR(IF(AND(ISNUMBER(D16), ISNUMBER(E16), D16*E16>0), D16*E16, ""), "") -> 4885.87
B17: =IFERROR(IF(AND(ISNUMBER(F17), F17>0), "Commission @30% of Main Services", ""), "") | D17: =IFERROR(INDEX('Payroll Data'!N:N, MATCH(B7, 'Payroll Data'!D:D, 0)), "") | E17: =IFERROR(INDEX('Payroll Data'!O:O, MATCH(B7, 'Payroll Data'!D:D, 0)), "") | F17: =IFERROR(IF(AND(ISNUMBER(D17), ISNUMBER(E17), D17*E17>0), D17*E17, ""), "")
B18: =IFERROR(IF(AND(ISNUMBER(F18), F18>0), "Overtime @ 1.5", ""), "") | D18: =IFERROR(INDEX('Payroll Data'!H:H, MATCH(B7, 'Payroll Data'!D:D, 0)), "") | E18: =IFERROR(IF(D18>0, ROUND(E16/Settings!$C$4*Settings!$C$5, 4), ""), "") -> 37.5836 | F18: =IFERROR(IF(AND(ISNUMBER(D18), ISNUMBER(E18), D18*E18>0), D18*E18, ""), "") | I18: 🖨️ PRINT PAYSLIP (A4) (Prints single-page A4 area)
B19: =IFERROR(IF(AND(ISNUMBER(F19), F19>0), "Annual Bonus @55%", ""), "") | D19: =IFERROR(IF(AND(ISNUMBER(E19), E19>0), 1, ""), "") | E19: =IFERROR(INDEX('Payroll Data'!Q:Q, MATCH(B7, 'Payroll Data'!D:D, 0)), "") | F19: =IFERROR(IF(AND(ISNUMBER(D19), ISNUMBER(E19), D19*E19>0), D19*E19, ""), "")
F20: =IFERROR(IF(AND(D20<>"", E20<>""), D20*E20, ""), "")
F21: =IFERROR(IF(AND(D21<>"", E21<>""), D21*E21, ""), "")
F22: =IFERROR(IF(AND(D22<>"", E22<>""), D22*E22, ""), "") | I22: 📊 PAYSLIP SUMMARY
F23: =IFERROR(IF(AND(D23<>"", E23<>""), D23*E23, ""), "") | I23: Gross Earnings: | J23: =F32 -> 4885.87
F24: =IFERROR(IF(AND(D24<>"", E24<>""), D24*E24, ""), "") | I24: Total Deductions: | J24: =F45 -> 48.86
F25: =IFERROR(IF(AND(D25<>"", E25<>""), D25*E25, ""), "") | I25: Net Pay Amount: | J25: =F47 -> 4837.01
F26: =IFERROR(IF(AND(D26<>"", E26<>""), D26*E26, ""), "")
F27: =IFERROR(IF(AND(D27<>"", E27<>""), D27*E27, ""), "")
F28: =IFERROR(IF(AND(D28<>"", E28<>""), D28*E28, ""), "")
F29: =IFERROR(IF(AND(D29<>"", E29<>""), D29*E29, ""), "")
F30: =IFERROR(IF(AND(D30<>"", E30<>""), D30*E30, ""), "")
E32: Total Payments | F32: =SUM(F16:F31) -> 4885.87
B34: DEDUCTIONS | F34: TOTAL
B35: =IFERROR(IF(AND(ISNUMBER(F35), F35>0), "PAYE", ""), "") | F35: =IFERROR(IF(INDEX('Payroll Data'!U:U, MATCH(B7, 'Payroll Data'!D:D, 0))>0, INDEX('Payroll Data'!U:U, MATCH(B7, 'Payroll Data'!D:D, 0)), ""), "")
B36: =IFERROR(IF(AND(ISNUMBER(F36), F36>0), "UIF", ""), "") -> UIF | F36: =IFERROR(IF(AND(ISNUMBER(F32), F32>0, ROUND(MIN(F32*Settings!$C$2, Settings!$C$3),2)>0), ROUND(MIN(F32*Settings!$C$2, Settings!$C$3),2), ""), "") -> 48.86
B37: Net Adjustments
B38: =IFERROR(IF(AND(ISNUMBER(F38), F38>0), "Medical Aid", ""), "") | F38: =IFERROR(IF(INDEX('Payroll Data'!W:W, MATCH(B7, 'Payroll Data'!D:D, 0))>0, INDEX('Payroll Data'!W:W, MATCH(B7, 'Payroll Data'!D:D, 0)), ""), "")
E45: Total Deductions | F45: =SUM(F35:F44) -> 48.86
E47: NET PAY | F47: =F32-F45 -> 4837.01
B49: Bank Name | D49: =IFERROR(VLOOKUP(B7, Employees!C:R, 12, FALSE()), "") -> Standard Bank South Africa
B50: Bank Account | D50: =IFERROR(VLOOKUP(B7, Employees!C:R, 13, FALSE()), "") -> 10293847561
B51: Account Type | D51: =IFERROR(VLOOKUP(B7, Employees!C:R, 14, FALSE()), "") -> Cheque / Current
B52: Payment Mode | D52: =IFERROR(VLOOKUP(B7, Employees!C:R, 15, FALSE()), "EFT") -> EFT
B56: =IFERROR(VLOOKUP(B2, Companies!B:J, 8, FALSE()), "Employee questions may be directed to business administration office : 49 Duncan Street, Witbank, 1039 010 824 9087 Or Managing Partner 0817657816") -> Employee questions may be directed to business administration office : 49 Duncan Street, Witbank, 1039 010 824 9087 Or Managing Partner 0817657816

Sheet Companies
A1: Company ID | B1: Company Name | C1: Trading Name / Legal Subtitle | D1: Address Line 1 | E1: Address Line 2 | F1: Website | G1: Phone Number | H1: Email Address | I1: Query Office / Footer Text | J1: Logo File | K1: Monthly Required Hours (NT Rule)
A2: COMP-001 | B2: Alora Dental Care | C2: Alora Dental Care | D2: Suite A4, Financial Square, Entrance 5 Ext 16 | E2: eMalahleni, 10359 | F2: www.aloradentalcare.co.za | G2: (013)656-1067 | H2: admin@aloradentalcare.co.za | I2: Employee questions may be directed to business administration office : 49 Duncan Street, Witbank, 1039 010 824 9087 Or Managing Partner 0817657816 | J2: #VALUE! | K2: 195
A3: COMP-002 | B3: Formalize | C3: S AND S KEMISTRY trading as Formalize. Reg: 2019 / 264478 / 07 | D3: 49 Duncan Street | E3: Emalahleni, 1034 | F3: www.formalize.co.za | G3: +27 10 824 9087 | H3: admin@formalize.co.za | I3: Employee questions may be directed to business administration office : 49 Duncan Street, Witbank, 1039 010 824 9087 Or Managing Partner 0817657816 | J3: =#VALUE! -> #VALUE! | K3: 195

Sheet Employees
A1: Company | B1: Employee Number | C1: Full Name | D1: ID Number | E1: Tax Reference Number | F1: Occupation / Designation | G1: Department | H1: Address | I1: Phone Number | J1: Email Address | K1: Payment Frequency | L1: Standard Basic Salary | M1: Standard Hourly Rate | N1: Bank Name | O1: Bank Account Number | P1: Account Type | Q1: Payment Mode | R1: Status | S1: Rank in Company (helper) | U1: Filtered Employees for Selected Company (helper)
A2: Formalize | B2: EMP-0001 | C2: Lindokuhle Edith Masilela | D2: 960405 0329 08 5 | F2: Accounts Administrator | G2: Accounts Management | H2: 49 Duncan Street, Witbank, 1039 | I2: +27 10 824 9087 | J2: lindokuhle@formalize.co.za | K2: Monthly | L2: 6690.42 | M2: =IFERROR(L2/INDEX(Companies!$K:$K,MATCH(A2,Companies!$B:$B,0)),"") -> 34.309846 | N2: Standard Bank South Africa | O2: 10149977458 | P2: Cheque / Current | Q2: EFT | R2: Active | S2: =IF($A2="","",COUNTIF($A$2:$A2,$A2)) -> 1 | U2: =IFERROR(INDEX($C$2:$C$301, SUMPRODUCT((($A$2:$A$301='Payslip Template'!$B$2)*($S$2:$S$300=1))*ROW($A$2:$A$301))-1), "")
A3: Formalize | B3: EMP-0002 | C3: Sizwe Hlatshwayo | D3: 880112 5567 082 | F3: Operations Manager | G3: Operations | H3: 49 Duncan Street, Witbank, 1039 | I3: +27 81 765 7816 | J3: sizwe@formalize.co.za | K3: Monthly | L3: 15000 | M3: =IFERROR(L3/INDEX(Companies!$K:$K,MATCH(A3,Companies!$B:$B,0)),"") -> 76.923077 | N3: First National Bank | O3: 62849102938 | P3: Cheque / Current | Q3: EFT | R3: Active | S3: =IF($A3="","",COUNTIF($A$2:$A3,$A3)) -> 2 | U3: =IFERROR(INDEX($C$2:$C$301, SUMPRODUCT((($A$2:$A$301='Payslip Template'!$B$2)*($S$2:$S$300=2))*ROW($A$2:$A$301))-1), "")
A4: Formalize | B4: EMP-0003 | C4: Wonder Hlatshwayo | D4: 920718 5123 089 | F4: Billing Administrator | G4: Billing | H4: 49 Duncan Street, Witbank, 1039 | I4: +27 72 345 6789 | J4: wonder@formalize.co.za | K4: Monthly | L4: 8500 | M4: =IFERROR(L4/INDEX(Companies!$K:$K,MATCH(A4,Companies!$B:$B,0)),"") -> 43.589744 | N4: Nedbank | O4: 1189456201 | P4: Savings | Q4: EFT | R4: Active | S4: =IF($A4="","",COUNTIF($A$2:$A4,$A4)) -> 3 | U4: =IFERROR(INDEX($C$2:$C$301, SUMPRODUCT((($A$2:$A$301='Payslip Template'!$B$2)*($S$2:$S$300=3))*ROW($A$2:$A$301))-1), "")
A5: Formalize | B5: EMP-0004 | C5: Tintswalo Makhubela | D5: 940322 0456 083 | F5: Billing Administrator | G5: Operations | H5: 49 Duncan Street, Witbank, 1039 | I5: +27 76 123 4567 | J5: tintswalo@formalize.co.za | K5: Monthly | L5: 7500 | M5: =IFERROR(L5/INDEX(Companies!$K:$K,MATCH(A5,Companies!$B:$B,0)),"") -> 38.461538 | N5: Standard Bank South Africa | O5: 10293847561 | P5: Cheque / Current | Q5: EFT | R5: Active | S5: =IF($A5="","",COUNTIF($A$2:$A5,$A5)) -> 4 | U5: =IFERROR(INDEX($C$2:$C$301, SUMPRODUCT((($A$2:$A$301='Payslip Template'!$B$2)*($S$2:$S$300=4))*ROW($A$2:$A$301))-1), "")
A6: Formalize | B6: EMP-0005 | C6: Doctor Khoza | D6: 900514 5678 084 | F6: HR | IT Specialist | G6: HR/IT | H6: 49 Duncan Street, Witbank, 1039 | I6: +27 82 987 6543 | J6: doctor@formalize.co.za | K6: Monthly | L6: 12000 | M6: =IFERROR(L6/INDEX(Companies!$K:$K,MATCH(A6,Companies!$B:$B,0)),"") -> 61.538462 | N6: First National Bank | O6: 62938471928 | P6: Cheque / Current | Q6: EFT | R6: Active | S6: =IF($A6="","",COUNTIF($A$2:$A6,$A6)) -> 5 | U6: =IFERROR(INDEX($C$2:$C$301, SUMPRODUCT((($A$2:$A$301='Payslip Template'!$B$2)*($S$2:$S$300=5))*ROW($A$2:$A$301))-1), "")
A7: Formalize | B7: EMP-0006 | C7: Whitney Nkosi | D7: 970815 0123 087 | F7: Administrative Assistant | G7: Operations | H7: 49 Duncan Street, Witbank, 1039 | I7: +27 71 234 5678 | J7: whitney@formalize.co.za | K7: Monthly | L7: 6500 | M7: =IFERROR(L7/INDEX(Companies!$K:$K,MATCH(A7,Companies!$B:$B,0)),"") -> 33.333333 | N7: Capitec Bank | O7: 1498765432 | P7: Savings | Q7: EFT | R7: Active | S7: =IF($A7="","",COUNTIF($A$2:$A7,$A7)) -> 6 | U7: =IFERROR(INDEX($C$2:$C$301, SUMPRODUCT((($A$2:$A$301='Payslip Template'!$B$2)*($S$2:$S$300=6))*ROW($A$2:$A$301))-1), "")
A8: Formalize | B8: EMP-0007 | C8: Precious Maphanga | D8: 950920 0789 081 | F8: Accounts Officer | G8: Accounts Management | H8: 49 Duncan Street, Witbank, 1039 | I8: +27 73 456 7890 | J8: precious@formalize.co.za | K8: Monthly | L8: 7000 | M8: =IFERROR(L8/INDEX(Companies!$K:$K,MATCH(A8,Companies!$B:$B,0)),"") -> 35.897436 | N8: Standard Bank South Africa | O8: 10384756291 | P8: Cheque / Current | Q8: EFT | R8: Active | S8: =IF($A8="","",COUNTIF($A$2:$A8,$A8)) -> 7 | U8: =IFERROR(INDEX($C$2:$C$301, SUMPRODUCT((($A$2:$A$301='Payslip Template'!$B$2)*($S$2:$S$300=7))*ROW($A$2:$A$301))-1), "")
A9: Alora Dental Care | B9: EMP-0008 | C9: Vasti Kmber Kruger | D9: 010619 0063 08 6 | F9: Front Desk Administrator | G9: Admin | H9: 50 SADC Street, Central Middelburg | I9: 063 509 1965 | J9: vastikruger@gmail.com | K9: Monthly | L9: 5894.4 | M9: =IFERROR(L9/INDEX(Companies!$K:$K,MATCH(A9,Companies!$B:$B,0)),"") -> 30.227692 | N9: Capitec Bank | P9: Savings | Q9: EFT | R9: Active | S9: =IF($A9="","",COUNTIF($A$2:$A9,$A9)) -> 1 | U9: =IFERROR(INDEX($C$2:$C$301, SUMPRODUCT((($A$2:$A$301='Payslip Template'!$B$2)*($S$2:$S$300=8))*ROW($A$2:$A$301))-1), "")
A10: Alora Dental Care | B10: EMP-0009 | C10: Matilda Dimakatso Segoane | D10: 851122 0770 08 3 | F10: CSSD Admin & Assistant | G10: Admin | H10: 3792 Setlake Street, Ackerville, Kwaguqa ,Emalahleni, 1039 | K10: Monthly | L10: 5894.4 | M10: =IFERROR(L10/INDEX(Companies!$K:$K,MATCH(A10,Companies!$B:$B,0)),"") -> 30.227692 | N10: Capitec Bank | O10: 11354626272 | P10: Savings | Q10: EFT | R10: Active | S10: =IF($A10="","",COUNTIF($A$2:$A11,$A10)) -> 3 | U10: =IFERROR(INDEX($C$2:$C$301, SUMPRODUCT((($A$2:$A$301='Payslip Template'!$B$2)*($S$2:$S$300=9))*ROW($A$2:$A$301))-1), "")
A11: Alora Dental Care | B11: EMP-0010 | C11: Kgomotso Bianca Mohlala | D11: 020714 0072 08 4 | F11: Temp Administrator | G11: Admin | H11: 10 Welma Street, Witbank, Witbank, 1035 | I11: 060 771 6495 | J11: bhekiwemohlala659@gmail.com | K11: Weekly | L11: 1090.365 | M11: 27.78 | N11: Capitec Bank | O11: 1818845189 | P11: Savings | Q11: EFT | R11: Inactive | S11: =IF($A12="","",COUNTIF($A$2:$A12,$A12)) | U11: =IFERROR(INDEX($C$2:$C$301, SUMPRODUCT((($A$2:$A$301='Payslip Template'!$B$2)*($S$2:$S$300=10))*ROW($A$2:$A$301))-1), "")
M12: =IFERROR(L12/INDEX(Companies!$K:$K,MATCH(A12,Companies!$B:$B,0)),"") | S12: =IF($A13="","",COUNTIF($A$2:$A13,$A13)) | U12: =IFERROR(INDEX($C$2:$C$301, SUMPRODUCT((($A$2:$A$301='Payslip Template'!$B$2)*($S$2:$S$300=11))*ROW($A$2:$A$301))-1), "")
M13: =IFERROR(L13/INDEX(Companies!$K:$K,MATCH(A13,Companies!$B:$B,0)),"") | S13: =IF($A14="","",COUNTIF($A$2:$A14,$A14)) | U13: =IFERROR(INDEX($C$2:$C$301, SUMPRODUCT((($A$2:$A$301='Payslip Template'!$B$2)*($S$2:$S$300=12))*ROW($A$2:$A$301))-1), "")
M14: =IFERROR(L14/INDEX(Companies!$K:$K,MATCH(A14,Companies!$B:$B,0)),"") | S14: =IF($A15="","",COUNTIF($A$2:$A15,$A15)) | U14: =IFERROR(INDEX($C$2:$C$301, SUMPRODUCT((($A$2:$A$301='Payslip Template'!$B$2)*($S$2:$S$300=13))*ROW($A$2:$A$301))-1), "")
M15: =IFERROR(L15/INDEX(Companies!$K:$K,MATCH(A15,Companies!$B:$B,0)),"") | S15: =IF($A16="","",COUNTIF($A$2:$A16,$A16)) | U15: =IFERROR(INDEX($C$2:$C$301, SUMPRODUCT((($A$2:$A$301='Payslip Template'!$B$2)*($S$2:$S$300=14))*ROW($A$2:$A$301))-1), "")
M16: =IFERROR(L16/INDEX(Companies!$K:$K,MATCH(A16,Companies!$B:$B,0)),"") | S16: =IF($A17="","",COUNTIF($A$2:$A17,$A17)) | U16: =IFERROR(INDEX($C$2:$C$301, SUMPRODUCT((($A$2:$A$301='Payslip Template'!$B$2)*($S$2:$S$300=15))*ROW($A$2:$A$301))-1), "")
M17: =IFERROR(L17/INDEX(Companies!$K:$K,MATCH(A17,Companies!$B:$B,0)),"") | S17: =IF($A18="","",COUNTIF($A$2:$A18,$A18)) | U17: =IFERROR(INDEX($C$2:$C$301, SUMPRODUCT((($A$2:$A$301='Payslip Template'!$B$2)*($S$2:$S$300=16))*ROW($A$2:$A$301))-1), "")
M18: =IFERROR(L18/INDEX(Companies!$K:$K,MATCH(A18,Companies!$B:$B,0)),"") | S18: =IF($A19="","",COUNTIF($A$2:$A19,$A19)) | U18: =IFERROR(INDEX($C$2:$C$301, SUMPRODUCT((($A$2:$A$301='Payslip Template'!$B$2)*($S$2:$S$300=17))*ROW($A$2:$A$301))-1), "")
M19: =IFERROR(L19/INDEX(Companies!$K:$K,MATCH(A19,Companies!$B:$B,0)),"") | S19: =IF($A20="","",COUNTIF($A$2:$A20,$A20)) | U19: =IFERROR(INDEX($C$2:$C$301, SUMPRODUCT((($A$2:$A$301='Payslip Template'!$B$2)*($S$2:$S$300=18))*ROW($A$2:$A$301))-1), "")
M20: =IFERROR(L20/INDEX(Companies!$K:$K,MATCH(A20,Companies!$B:$B,0)),"") | S20: =IF($A21="","",COUNTIF($A$2:$A21,$A21)) | U20: =IFERROR(INDEX($C$2:$C$301, SUMPRODUCT((($A$2:$A$301='Payslip Template'!$B$2)*($S$2:$S$300=19))*ROW($A$2:$A$301))-1), "")
M21: =IFERROR(L21/INDEX(Companies!$K:$K,MATCH(A21,Companies!$B:$B,0)),"") | S21: =IF($A22="","",COUNTIF($A$2:$A22,$A22)) | U21: =IFERROR(INDEX($C$2:$C$301, SUMPRODUCT((($A$2:$A$301='Payslip Template'!$B$2)*($S$2:$S$300=20))*ROW($A$2:$A$301))-1), "")
M22: =IFERROR(L22/INDEX(Companies!$K:$K,MATCH(A22,Companies!$B:$B,0)),"") | S22: =IF($A23="","",COUNTIF($A$2:$A23,$A23)) | U22: =IFERROR(INDEX($C$2:$C$301, SUMPRODUCT((($A$2:$A$301='Payslip Template'!$B$2)*($S$2:$S$300=21))*ROW($A$2:$A$301))-1), "")
M23: =IFERROR(L23/INDEX(Companies!$K:$K,MATCH(A23,Companies!$B:$B,0)),"") | S23: =IF($A24="","",COUNTIF($A$2:$A24,$A24)) | U23: =IFERROR(INDEX($C$2:$C$301, SUMPRODUCT((($A$2:$A$301='Payslip Template'!$B$2)*($S$2:$S$300=22))*ROW($A$2:$A$301))-1), "")
M24: =IFERROR(L24/INDEX(Companies!$K:$K,MATCH(A24,Companies!$B:$B,0)),"") | S24: =IF($A25="","",COUNTIF($A$2:$A25,$A25)) | U24: =IFERROR(INDEX($C$2:$C$301, SUMPRODUCT((($A$2:$A$301='Payslip Template'!$B$2)*($S$2:$S$300=23))*ROW($A$2:$A$301))-1), "")
M25: =IFERROR(L25/INDEX(Companies!$K:$K,MATCH(A25,Companies!$B:$B,0)),"") | S25: =IF($A26="","",COUNTIF($A$2:$A26,$A26)) | U25: =IFERROR(INDEX($C$2:$C$301, SUMPRODUCT((($A$2:$A$301='Payslip Template'!$B$2)*($S$2:$S$300=24))*ROW($A$2:$A$301))-1), "")
M26: =IFERROR(L26/INDEX(Companies!$K:$K,MATCH(A26,Companies!$B:$B,0)),"") | S26: =IF($A27="","",COUNTIF($A$2:$A27,$A27)) | U26: =IFERROR(INDEX($C$2:$C$301, SUMPRODUCT((($A$2:$A$301='Payslip Template'!$B$2)*($S$2:$S$300=25))*ROW($A$2:$A$301))-1), "")
M27: =IFERROR(L27/INDEX(Companies!$K:$K,MATCH(A27,Companies!$B:$B,0)),"") | S27: =IF($A28="","",COUNTIF($A$2:$A28,$A28)) | U27: =IFERROR(INDEX($C$2:$C$301, SUMPRODUCT((($A$2:$A$301='Payslip Template'!$B$2)*($S$2:$S$300=26))*ROW($A$2:$A$301))-1), "")
M28: =IFERROR(L28/INDEX(Companies!$K:$K,MATCH(A28,Companies!$B:$B,0)),"") | S28: =IF($A29="","",COUNTIF($A$2:$A29,$A29)) | U28: =IFERROR(INDEX($C$2:$C$301, SUMPRODUCT((($A$2:$A$301='Payslip Template'!$B$2)*($S$2:$S$300=27))*ROW($A$2:$A$301))-1), "")
M29: =IFERROR(L29/INDEX(Companies!$K:$K,MATCH(A29,Companies!$B:$B,0)),"") | S29: =IF($A30="","",COUNTIF($A$2:$A30,$A30)) | U29: =IFERROR(INDEX($C$2:$C$301, SUMPRODUCT((($A$2:$A$301='Payslip Template'!$B$2)*($S$2:$S$300=28))*ROW($A$2:$A$301))-1), "")
M30: =IFERROR(L30/INDEX(Companies!$K:$K,MATCH(A30,Companies!$B:$B,0)),"") | S30: =IF($A31="","",COUNTIF($A$2:$A31,$A31)) | U30: =IFERROR(INDEX($C$2:$C$301, SUMPRODUCT((($A$2:$A$301='Payslip Template'!$B$2)*($S$2:$S$300=29))*ROW($A$2:$A$301))-1), "")
M31: =IFERROR(L31/INDEX(Companies!$K:$K,MATCH(A31,Companies!$B:$B,0)),"") | S31: =IF($A32="","",COUNTIF($A$2:$A32,$A32)) | U31: =IFERROR(INDEX($C$2:$C$301, SUMPRODUCT((($A$2:$A$301='Payslip Template'!$B$2)*($S$2:$S$300=30))*ROW($A$2:$A$301))-1), "")
M32: =IFERROR(L32/INDEX(Companies!$K:$K,MATCH(A32,Companies!$B:$B,0)),"") | S32: =IF($A33="","",COUNTIF($A$2:$A33,$A33)) | U32: =IFERROR(INDEX($C$2:$C$301, SUMPRODUCT((($A$2:$A$301='Payslip Template'!$B$2)*($S$2:$S$300=31))*ROW($A$2:$A$301))-1), "")
M33: =IFERROR(L33/INDEX(Companies!$K:$K,MATCH(A33,Companies!$B:$B,0)),"") | S33: =IF($A34="","",COUNTIF($A$2:$A34,$A34)) | U33: =IFERROR(INDEX($C$2:$C$301, SUMPRODUCT((($A$2:$A$301='Payslip Template'!$B$2)*($S$2:$S$300=32))*ROW($A$2:$A$301))-1), "")
M34: =IFERROR(L34/INDEX(Companies!$K:$K,MATCH(A34,Companies!$B:$B,0)),"") | S34: =IF($A35="","",COUNTIF($A$2:$A35,$A35)) | U34: =IFERROR(INDEX($C$2:$C$301, SUMPRODUCT((($A$2:$A$301='Payslip Template'!$B$2)*($S$2:$S$300=33))*ROW($A$2:$A$301))-1), "")
M35: =IFERROR(L35/INDEX(Companies!$K:$K,MATCH(A35,Companies!$B:$B,0)),"") | S35: =IF($A36="","",COUNTIF($A$2:$A36,$A36)) | U35: =IFERROR(INDEX($C$2:$C$301, SUMPRODUCT((($A$2:$A$301='Payslip Template'!$B$2)*($S$2:$S$300=34))*ROW($A$2:$A$301))-1), "")
M36: =IFERROR(L36/INDEX(Companies!$K:$K,MATCH(A36,Companies!$B:$B,0)),"") | S36: =IF($A37="","",COUNTIF($A$2:$A37,$A37)) | U36: =IFERROR(INDEX($C$2:$C$301, SUMPRODUCT((($A$2:$A$301='Payslip Template'!$B$2)*($S$2:$S$300=35))*ROW($A$2:$A$301))-1), "")
M37: =IFERROR(L37/INDEX(Companies!$K:$K,MATCH(A37,Companies!$B:$B,0)),"") | S37: =IF($A38="","",COUNTIF($A$2:$A38,$A38)) | U37: =IFERROR(INDEX($C$2:$C$301, SUMPRODUCT((($A$2:$A$301='Payslip Template'!$B$2)*($S$2:$S$300=36))*ROW($A$2:$A$301))-1), "")
M38: =IFERROR(L38/INDEX(Companies!$K:$K,MATCH(A38,Companies!$B:$B,0)),"") | S38: =IF($A39="","",COUNTIF($A$2:$A39,$A39)) | U38: =IFERROR(INDEX($C$2:$C$301, SUMPRODUCT((($A$2:$A$301='Payslip Template'!$B$2)*($S$2:$S$300=37))*ROW($A$2:$A$301))-1), "")
M39: =IFERROR(L39/INDEX(Companies!$K:$K,MATCH(A39,Companies!$B:$B,0)),"") | S39: =IF($A40="","",COUNTIF($A$2:$A40,$A40)) | U39: =IFERROR(INDEX($C$2:$C$301, SUMPRODUCT((($A$2:$A$301='Payslip Template'!$B$2)*($S$2:$S$300=38))*ROW($A$2:$A$301))-1), "")
M40: =IFERROR(L40/INDEX(Companies!$K:$K,MATCH(A40,Companies!$B:$B,0)),"") | S40: =IF($A41="","",COUNTIF($A$2:$A41,$A41)) | U40: =IFERROR(INDEX($C$2:$C$301, SUMPRODUCT((($A$2:$A$301='Payslip Template'!$B$2)*($S$2:$S$300=39))*ROW($A$2:$A$301))-1), "")
...

Sheet Payroll Data
A1: Pay Period | B1: Pay Date | C1: Company | D1: Employee Name | E1: Basic Salary | F1: Normal Hours | G1: Hourly Rate | H1: OT 1.5x Hours | I1: OT 1.5x Rate | J1: OT 1.5x Total | K1: OT 2.0x Hours | L1: OT 2.0x Rate | M1: OT 2.0x Total | N1: Commission Base | O1: Commission Rate | P1: Commission Total | Q1: Annual Bonus | R1: Performance Bonus | S1: Travel Allowance | T1: Other Allowance | U1: PAYE (Tax) | V1: UIF Amount | W1: Medical Aid | X1: Pension Fund | Y1: Staff Loan | Z1: Unpaid Absence | AA1: Other Deductions | AB1: Gross Earnings | AC1: Total Deductions | AD1: Net Pay | AF1: KEY
A2: December 2025 | B2: 23/12/2025 | C2: Alora Dental Care | D2: NOMATHEMBA BIANCA MAHLANGU | E2: =IFERROR(INDEX(Employees!$L:$L,SUMPRODUCT((Employees!$A$2:$A$102=C2)*(Employees!$C$2:$C$102=D2)*ROW(Employees!$A$2:$A$102))),"") -> 6690.42 | F2: 195 | G2: =IFERROR(INDEX(Employees!$M:$M,SUMPRODUCT((Employees!$A$2:$A$102=C2)*(Employees!$C$2:$C$102=D2)*ROW(Employees!$A$2:$A$102))),"") -> 34.309846 | H2: 22.33 | I2: =IFERROR(ROUND(G2*Settings!$C$5,4),"") -> 51.4648 | J2: =IFERROR(ROUND(H2*I2,2),"") -> 1149.21 | K2: 0 | L2: =IFERROR(ROUND(G2*Settings!$C$6,4),"") -> 68.6197 | M2: =IFERROR(ROUND(K2*L2,2),0) -> 0 | N2: 470 | O2: 0.3 | P2: =IFERROR(ROUND(N2*O2,2),"") -> 141 | Q2: 2687.23 | R2: 0 | S2: 0 | T2: 0 | U2: 0 | V2: 0 | W2: 0 | X2: 0 | Y2: 0 | Z2: 0 | AA2: 0 | AB2: =SUM(E2,J2,M2,P2,Q2,R2,S2,T2) -> 10667.86 | AC2: =SUM(U2,V2,W2,X2,Y2,Z2,AA2) -> 0 | AD2: =AB2-AC2 -> 10667.86 | AG2: Yellow = enter payroll data here
A3: May 2026 | B3: 25/05/2026 | C3: Formalize | D3: Lindokuhle Edith Masilela | E3: =IFERROR(INDEX(Employees!$L:$L,SUMPRODUCT((Employees!$A$2:$A$102=C3)*(Employees!$C$2:$C$102=D3)*ROW(Employees!$A$2:$A$102))),"") -> 6690.42 | F3: 195 | G3: =IFERROR(INDEX(Employees!$M:$M,SUMPRODUCT((Employees!$A$2:$A$102=C3)*(Employees!$C$2:$C$102=D3)*ROW(Employees!$A$2:$A$102))),"") -> 34.309846 | H3: 0 | I3: =IFERROR(ROUND(G3*Settings!$C$5,4),"") -> 51.4648 | J3: =IFERROR(ROUND(H3*I3,2),"") -> 0 | K3: 0 | L3: =IFERROR(ROUND(G3*Settings!$C$6,4),"") -> 68.6197 | M3: =IFERROR(ROUND(K3*L3,2),0) -> 0 | N3: 0 | O3: 0 | P3: =IFERROR(ROUND(N3*O3,2),"") -> 0 | Q3: 0 | R3: 0 | S3: 0 | T3: 0 | U3: 0 | V3: 0 | W3: 0 | X3: 0 | Y3: 0 | Z3: 0 | AA3: 0 | AB3: =SUM(E3,J3,M3,P3,Q3,R3,S3,T3) -> 6690.42 | AC3: =SUM(U3,V3,W3,X3,Y3,Z3,AA3) -> 0 | AD3: =AB3-AC3 -> 6690.42 | AG3: Grey/italic = auto-calculated — do not type over
A4: September 2026 | B4: 25/09/2026 | C4: Formalize | D4: Wonder Hlatshwayo | E4: =IFERROR(INDEX(Employees!$L:$L,SUMPRODUCT((Employees!$A$2:$A$102=C4)*(Employees!$C$2:$C$102=D4)*ROW(Employees!$A$2:$A$102))),"") -> 8500 | F4: 195 | G4: =IFERROR(INDEX(Employees!$M:$M,SUMPRODUCT((Employees!$A$2:$A$102=C4)*(Employees!$C$2:$C$102=D4)*ROW(Employees!$A$2:$A$102))),"") -> 43.589744 | H4: 12.5 | I4: =IFERROR(ROUND(G4*Settings!$C$5,4),"") -> 65.3846 | J4: =IFERROR(ROUND(H4*I4,2),"") -> 817.31 | K4: 0 | L4: =IFERROR(ROUND(G4*Settings!$C$6,4),"") -> 87.1795 | M4: =IFERROR(ROUND(K4*L4,2),0) -> 0 | N4: 0 | O4: 0 | P4: =IFERROR(ROUND(N4*O4,2),"") -> 0 | Q4: 0 | R4: 500 | S4: 250 | T4: 0 | U4: 0 | V4: 0 | W4: 0 | X4: 0 | Y4: 0 | Z4: 0 | AA4: 0 | AB4: =SUM(E4,J4,M4,P4,Q4,R4,S4,T4) -> 10067.31 | AC4: =SUM(U4,V4,W4,X4,Y4,Z4,AA4) -> 0 | AD4: =AB4-AC4 -> 10067.31
A5: September 2026 | C5: Alora Dental Care | D5: Vasti Kmber Kruger | E5: =IFERROR(INDEX(Employees!$L:$L,SUMPRODUCT((Employees!$A$2:$A$102=C5)*(Employees!$C$2:$C$102=D5)*ROW(Employees!$A$2:$A$102))),"") -> 5894.4 | F5: 195 | G5: =IFERROR(INDEX(Employees!$M:$M,SUMPRODUCT((Employees!$A$2:$A$102=C5)*(Employees!$C$2:$C$102=D5)*ROW(Employees!$A$2:$A$102))),"") -> 30.227692 | H5: 2 | I5: =IFERROR(ROUND(G5*Settings!$C$5,4),"") -> 45.3415 | J5: =IFERROR(ROUND(H5*I5,2),"") -> 90.68 | K5: 0 | L5: =IFERROR(ROUND(G5*Settings!$C$6,4),"") -> 60.4554 | M5: =IFERROR(ROUND(K5*L5,2),0) -> 0 | N5: 0 | O5: 0 | P5: =IFERROR(ROUND(N5*O5,2),"") -> 0 | Q5: 0 | R5: 0 | S5: 0 | T5: 0 | U5: 0 | V5: 0 | W5: 0 | X5: 0 | Y5: 0 | Z5: 0 | AA5: 0 | AB5: =SUM(E5,J5,M5,P5,Q5,R5,S5,T5) -> 5985.08 | AC5: =SUM(U5,V5,W5,X5,Y5,Z5,AA5) -> 0 | AD5: =AB5-AC5 -> 5985.08
E6: =IFERROR(INDEX(Employees!$L:$L,SUMPRODUCT((Employees!$A$2:$A$102=C6)*(Employees!$C$2:$C$102=D6)*ROW(Employees!$A$2:$A$102))),"") -> 0 | G6: =IFERROR(INDEX(Employees!$M:$M,SUMPRODUCT((Employees!$A$2:$A$102=C6)*(Employees!$C$2:$C$102=D6)*ROW(Employees!$A$2:$A$102))),"") -> 0 | I6: =IFERROR(ROUND(G6*Settings!$C$5,4),"") -> 0 | J6: =IFERROR(ROUND(H6*I6,2),"") -> 0 | L6: =IFERROR(ROUND(G6*Settings!$C$6,4),"") -> 0 | M6: =IFERROR(ROUND(K6*L6,2),0) -> 0 | P6: =IFERROR(ROUND(N6*O6,2),"") -> 0 | AB6: =SUM(E6,J6,M6,P6,Q6,R6,S6,T6) -> 0 | AC6: =SUM(U6,V6,W6,X6,Y6,Z6,AA6) -> 0 | AD6: =AB6-AC6 -> 0
E7: =IFERROR(INDEX(Employees!$L:$L,SUMPRODUCT((Employees!$A$2:$A$102=C7)*(Employees!$C$2:$C$102=D7)*ROW(Employees!$A$2:$A$102))),"") -> 0 | G7: =IFERROR(INDEX(Employees!$M:$M,SUMPRODUCT((Employees!$A$2:$A$102=C7)*(Employees!$C$2:$C$102=D7)*ROW(Employees!$A$2:$A$102))),"") -> 0 | I7: =IFERROR(ROUND(G7*Settings!$C$5,4),"") -> 0 | J7: =IFERROR(ROUND(H7*I7,2),"") -> 0 | L7: =IFERROR(ROUND(G7*Settings!$C$6,4),"") -> 0 | M7: =IFERROR(ROUND(K7*L7,2),0) -> 0 | P7: =IFERROR(ROUND(N7*O7,2),"") -> 0 | AB7: =SUM(E7,J7,M7,P7,Q7,R7,S7,T7) -> 0 | AC7: =SUM(U7,V7,W7,X7,Y7,Z7,AA7) -> 0 | AD7: =AB7-AC7 -> 0
E8: =IFERROR(INDEX(Employees!$L:$L,SUMPRODUCT((Employees!$A$2:$A$102=C8)*(Employees!$C$2:$C$102=D8)*ROW(Employees!$A$2:$A$102))),"") -> 0 | G8: =IFERROR(INDEX(Employees!$M:$M,SUMPRODUCT((Employees!$A$2:$A$102=C8)*(Employees!$C$2:$C$102=D8)*ROW(Employees!$A$2:$A$102))),"") -> 0 | I8: =IFERROR(ROUND(G8*Settings!$C$5,4),"") -> 0 | J8: =IFERROR(ROUND(H8*I8,2),"") -> 0 | L8: =IFERROR(ROUND(G8*Settings!$C$6,4),"") -> 0 | M8: =IFERROR(ROUND(K8*L8,2),0) -> 0 | P8: =IFERROR(ROUND(N8*O8,2),"") -> 0 | AB8: =SUM(E8,J8,M8,P8,Q8,R8,S8,T8) -> 0 | AC8: =SUM(U8,V8,W8,X8,Y8,Z8,AA8) -> 0 | AD8: =AB8-AC8 -> 0
E9: =IFERROR(INDEX(Employees!$L:$L,SUMPRODUCT((Employees!$A$2:$A$102=C9)*(Employees!$C$2:$C$102=D9)*ROW(Employees!$A$2:$A$102))),"") -> 0 | G9: =IFERROR(INDEX(Employees!$M:$M,SUMPRODUCT((Employees!$A$2:$A$102=C9)*(Employees!$C$2:$C$102=D9)*ROW(Employees!$A$2:$A$102))),"") -> 0 | I9: =IFERROR(ROUND(G9*Settings!$C$5,4),"") -> 0 | J9: =IFERROR(ROUND(H9*I9,2),"") -> 0 | L9: =IFERROR(ROUND(G9*Settings!$C$6,4),"") -> 0 | M9: =IFERROR(ROUND(K9*L9,2),0) -> 0 | P9: =IFERROR(ROUND(N9*O9,2),"") -> 0 | AB9: =SUM(E9,J9,M9,P9,Q9,R9,S9,T9) -> 0 | AC9: =SUM(U9,V9,W9,X9,Y9,Z9,AA9) -> 0 | AD9: =AB9-AC9 -> 0
E10: =IFERROR(INDEX(Employees!$L:$L,SUMPRODUCT((Employees!$A$2:$A$102=C10)*(Employees!$C$2:$C$102=D10)*ROW(Employees!$A$2:$A$102))),"") -> 0 | G10: =IFERROR(INDEX(Employees!$M:$M,SUMPRODUCT((Employees!$A$2:$A$102=C10)*(Employees!$C$2:$C$102=D10)*ROW(Employees!$A$2:$A$102))),"") -> 0 | I10: =IFERROR(ROUND(G10*Settings!$C$5,4),"") -> 0 | J10: =IFERROR(ROUND(H10*I10,2),"") -> 0 | L10: =IFERROR(ROUND(G10*Settings!$C$6,4),"") -> 0 | M10: =IFERROR(ROUND(K10*L10,2),0) -> 0 | P10: =IFERROR(ROUND(N10*O10,2),"") -> 0 | AB10: =SUM(E10,J10,M10,P10,Q10,R10,S10,T10) -> 0 | AC10: =SUM(U10,V10,W10,X10,Y10,Z10,AA10) -> 0 | AD10: =AB10-AC10 -> 0
E11: =IFERROR(INDEX(Employees!$L:$L,SUMPRODUCT((Employees!$A$2:$A$102=C11)*(Employees!$C$2:$C$102=D11)*ROW(Employees!$A$2:$A$102))),"") -> 0 | G11: =IFERROR(INDEX(Employees!$M:$M,SUMPRODUCT((Employees!$A$2:$A$102=C11)*(Employees!$C$2:$C$102=D11)*ROW(Employees!$A$2:$A$102))),"") -> 0 | I11: =IFERROR(ROUND(G11*Settings!$C$5,4),"") -> 0 | J11: =IFERROR(ROUND(H11*I11,2),"") -> 0 | L11: =IFERROR(ROUND(G11*Settings!$C$6,4),"") -> 0 | M11: =IFERROR(ROUND(K11*L11,2),0) -> 0 | P11: =IFERROR(ROUND(N11*O11,2),"") -> 0 | AB11: =SUM(E11,J11,M11,P11,Q11,R11,S11,T11) -> 0 | AC11: =SUM(U11,V11,W11,X11,Y11,Z11,AA11) -> 0 | AD11: =AB11-AC11 -> 0
E12: =IFERROR(INDEX(Employees!$L:$L,SUMPRODUCT((Employees!$A$2:$A$102=C12)*(Employees!$C$2:$C$102=D12)*ROW(Employees!$A$2:$A$102))),"") -> 0 | G12: =IFERROR(INDEX(Employees!$M:$M,SUMPRODUCT((Employees!$A$2:$A$102=C12)*(Employees!$C$2:$C$102=D12)*ROW(Employees!$A$2:$A$102))),"") -> 0 | I12: =IFERROR(ROUND(G12*Settings!$C$5,4),"") -> 0 | J12: =IFERROR(ROUND(H12*I12,2),"") -> 0 | L12: =IFERROR(ROUND(G12*Settings!$C$6,4),"") -> 0 | M12: =IFERROR(ROUND(K12*L12,2),0) -> 0 | P12: =IFERROR(ROUND(N12*O12,2),"") -> 0 | AB12: =SUM(E12,J12,M12,P12,Q12,R12,S12,T12) -> 0 | AC12: =SUM(U12,V12,W12,X12,Y12,Z12,AA12) -> 0 | AD12: =AB12-AC12 -> 0
E13: =IFERROR(INDEX(Employees!$L:$L,SUMPRODUCT((Employees!$A$2:$A$102=C13)*(Employees!$C$2:$C$102=D13)*ROW(Employees!$A$2:$A$102))),"") -> 0 | G13: =IFERROR(INDEX(Employees!$M:$M,SUMPRODUCT((Employees!$A$2:$A$102=C13)*(Employees!$C$2:$C$102=D13)*ROW(Employees!$A$2:$A$102))),"") -> 0 | I13: =IFERROR(ROUND(G13*Settings!$C$5,4),"") -> 0 | J13: =IFERROR(ROUND(H13*I13,2),"") -> 0 | L13: =IFERROR(ROUND(G13*Settings!$C$6,4),"") -> 0 | M13: =IFERROR(ROUND(K13*L13,2),0) -> 0 | P13: =IFERROR(ROUND(N13*O13,2),"") -> 0 | AB13: =SUM(E13,J13,M13,P13,Q13,R13,S13,T13) -> 0 | AC13: =SUM(U13,V13,W13,X13,Y13,Z13,AA13) -> 0 | AD13: =AB13-AC13 -> 0
E14: =IFERROR(INDEX(Employees!$L:$L,SUMPRODUCT((Employees!$A$2:$A$102=C14)*(Employees!$C$2:$C$102=D14)*ROW(Employees!$A$2:$A$102))),"") -> 0 | G14: =IFERROR(INDEX(Employees!$M:$M,SUMPRODUCT((Employees!$A$2:$A$102=C14)*(Employees!$C$2:$C$102=D14)*ROW(Employees!$A$2:$A$102))),"") -> 0 | I14: =IFERROR(ROUND(G14*Settings!$C$5,4),"") -> 0 | J14: =IFERROR(ROUND(H14*I14,2),"") -> 0 | L14: =IFERROR(ROUND(G14*Settings!$C$6,4),"") -> 0 | M14: =IFERROR(ROUND(K14*L14,2),0) -> 0 | P14: =IFERROR(ROUND(N14*O14,2),"") -> 0 | AB14: =SUM(E14,J14,M14,P14,Q14,R14,S14,T14) -> 0 | AC14: =SUM(U14,V14,W14,X14,Y14,Z14,AA14) -> 0 | AD14: =AB14-AC14 -> 0
E15: =IFERROR(INDEX(Employees!$L:$L,SUMPRODUCT((Employees!$A$2:$A$102=C15)*(Employees!$C$2:$C$102=D15)*ROW(Employees!$A$2:$A$102))),"") -> 0 | G15: =IFERROR(INDEX(Employees!$M:$M,SUMPRODUCT((Employees!$A$2:$A$102=C15)*(Employees!$C$2:$C$102=D15)*ROW(Employees!$A$2:$A$102))),"") -> 0 | I15: =IFERROR(ROUND(G15*Settings!$C$5,4),"") -> 0 | J15: =IFERROR(ROUND(H15*I15,2),"") -> 0 | L15: =IFERROR(ROUND(G15*Settings!$C$6,4),"") -> 0 | M15: =IFERROR(ROUND(K15*L15,2),0) -> 0 | P15: =IFERROR(ROUND(N15*O15,2),"") -> 0 | AB15: =SUM(E15,J15,M15,P15,Q15,R15,S15,T15) -> 0 | AC15: =SUM(U15,V15,W15,X15,Y15,Z15,AA15) -> 0 | AD15: =AB15-AC15 -> 0
E16: =IFERROR(INDEX(Employees!$L:$L,SUMPRODUCT((Employees!$A$2:$A$102=C16)*(Employees!$C$2:$C$102=D16)*ROW(Employees!$A$2:$A$102))),"") -> 0 | G16: =IFERROR(INDEX(Employees!$M:$M,SUMPRODUCT((Employees!$A$2:$A$102=C16)*(Employees!$C$2:$C$102=D16)*ROW(Employees!$A$2:$A$102))),"") -> 0 | I16: =IFERROR(ROUND(G16*Settings!$C$5,4),"") -> 0 | J16: =IFERROR(ROUND(H16*I16,2),"") -> 0 | L16: =IFERROR(ROUND(G16*Settings!$C$6,4),"") -> 0 | M16: =IFERROR(ROUND(K16*L16,2),0) -> 0 | P16: =IFERROR(ROUND(N16*O16,2),"") -> 0 | AB16: =SUM(E16,J16,M16,P16,Q16,R16,S16,T16) -> 0 | AC16: =SUM(U16,V16,W16,X16,Y16,Z16,AA16) -> 0 | AD16: =AB16-AC16 -> 0
E17: =IFERROR(INDEX(Employees!$L:$L,SUMPRODUCT((Employees!$A$2:$A$102=C17)*(Employees!$C$2:$C$102=D17)*ROW(Employees!$A$2:$A$102))),"") -> 0 | G17: =IFERROR(INDEX(Employees!$M:$M,SUMPRODUCT((Employees!$A$2:$A$102=C17)*(Employees!$C$2:$C$102=D17)*ROW(Employees!$A$2:$A$102))),"") -> 0 | I17: =IFERROR(ROUND(G17*Settings!$C$5,4),"") -> 0 | J17: =IFERROR(ROUND(H17*I17,2),"") -> 0 | L17: =IFERROR(ROUND(G17*Settings!$C$6,4),"") -> 0 | M17: =IFERROR(ROUND(K17*L17,2),0) -> 0 | P17: =IFERROR(ROUND(N17*O17,2),"") -> 0 | AB17: =SUM(E17,J17,M17,P17,Q17,R17,S17,T17) -> 0 | AC17: =SUM(U17,V17,W17,X17,Y17,Z17,AA17) -> 0 | AD17: =AB17-AC17 -> 0
... E100: =IFERROR(INDEX(Employees!$L:$L,SUMPRODUCT((Employees!$A$2:$A$102=C100)*(Employees!$C$2:$C$102=D100)*ROW(Employees!$A$2:$A$102))),"") -> 0 | G100: =IFERROR(INDEX(Employees!$M:$M,SUMPRODUCT((Employees!$A$2:$A$102=C100)*(Employees!$C$2:$C$102=D100)*ROW(Employees!$A$2:$A$102))),"") -> 0 | I100: =IFERROR(ROUND(G100*Settings!$C$5,4),"") -> 0 | J100: =IFERROR(ROUND(H100*I100,2),"") -> 0 | L100: =IFERROR(ROUND(G100*Settings!$C$6,4),"") -> 0 | M100: =IFERROR(ROUND(K100*L100,2),0) -> 0 | P100: =IFERROR(ROUND(N100*O100,2),"") -> 0 | AB100: =SUM(E100,J100,M100,P100,Q100,R100,S100,T100) -> 0 | AC100: =SUM(U100,V100,W100,X100,Y100,Z100,AA100) -> 0 | AD100: =AB100-AC100 -> 0

Sheet Settings
A1: Category | B1: Parameter Name | C1: Value | D1: Description / Notes | F1: Pay Frequencies | H1: Account Types | J1: Earnings Catalog | L1: Payment Modes | N1: Employee Status
A2: Statutory | B2: UIF Employee Rate | C2: 0.01 | D2: 1.0% statutory employee contribution | F2: Monthly | H2: Cheque / Current | J2: Basic Salary | L2: EFT | N2: Active
A3: Statutory | B3: UIF Statutory Monthly Cap | C3: 177.12 | D3: Maximum statutory deduction (R 177.12 / month) | F3: Weekly | H3: Savings | J3: Commission | L3: Cash | N3: Inactive
A4: Hours | B4: Standard Monthly Hours | C4: 195 | D4: Default monthly hours baseline | F4: Fortnightly | H4: Transmission | J4: Overtime @ 1.5 | L4: Cheque | N4: Suspended
A5: Overtime | B5: Overtime Multiplier Normal | C5: 1.5 | D5: 1.5x regular hourly rate for standard OT | J5: Overtime @ 2.0 | N5: Terminated
A6: Overtime | B6: Overtime Multiplier Sunday | C6: 2 | D6: 2.0x regular hourly rate for Sundays / Holidays | J6: Annual Bonus
A7: System | B7: PDF Export Folder | C7: Payslips\ | D7: Default folder for exported PDF files | J7: Performance Bonus
J8: Travel Allowance
J9: Housing Allowance
J10: Cellphone Allowance
J11: Backpay / Adjustment
